程序发生异常时，使用 `panic` 来终止程序，当程序发生 `panic` 时，使用 `recover` 可以重新获得该程序的控制。
## 什么时候应该使用 panic？
需要注意的是，应该尽可能使用错误，而不是 `panic` 和 `recover`。只有当程序不能继续运行的时候，才应该使用 `panic` 和 `recover` 机制。
## panic 示例
内建 `panic` 签名
```go
func panic(interface{})
```
程序终止时，会打印传入 panic 的参数
```go
func fullName(firstName *string, lastName *string) {  
    if firstName == nil {
        panic("runtime error: first name cannot be nil")
    }
    if lastName == nil {    //程序第 12 行，程序发生 panic
        panic("runtime error: last name cannot be nil")
    }
    fmt.Printf("%s %s\n", *firstName, *lastName)     //panic 之后不会运行
    fmt.Println("returned normally from fullName")   //panic 之后不会运行
}

func main() {  
    firstName := "Elon"
    fullName(&firstName, nil)     //程序第 20 行
    fmt.Println("returned normally from main")
}
```
程序输出
```go
panic: runtime error: last name cannot be nil    //当出现 panic 程序就会终止运行，打印传入 panic 的参数，

goroutine 1 [running]:  
main.fullName(0x1040c128, 0x0)  
    /tmp/sandbox135038844/main.go:12 +0x120    //程序在 12 行发生 panic，首先打印 12 行的错误堆栈
main.main()  
    /tmp/sandbox135038844/main.go:20 +0x80     //20 行调用 12 行异常，于是错误堆栈接着打印这行
```
## 发生 panic 时的 defer
`panic`发生后首先终止运行，执行完所有的 `defer` 函数后，程序控制返回到该函数的调用方。这个过程会一直持续，直到当前协程的所有函数都返回退出，然后打印 `panic` 信息，接着打印堆栈跟踪，最后程序终止。
```go
func fullName(firstName *string, lastName *string) {  
    defer fmt.Println("deferred call in fullName")
    if firstName == nil {
        panic("runtime error: first name cannot be nil")
    }
    if lastName == nil {   //第 13 行
        panic("runtime error: last name cannot be nil")
    }
    fmt.Printf("%s %s\n", *firstName, *lastName)
    fmt.Println("returned normally from fullName")
}

func main() {  
    defer fmt.Println("deferred call in main")
    firstName := "Elon"
    fullName(&firstName, nil)
    fmt.Println("returned normally from main")
}
```
程序输出
```go
deferred call in fullName  
deferred call in main  
panic: runtime error: last name cannot be nil

goroutine 1 [running]:  
main.fullName(0x1042bf90, 0x0)  
    /tmp/sandbox060731990/main.go:13 +0x280
main.main()  
    /tmp/sandbox060731990/main.go:22 +0xc0
```
执行到 13 行发生 `panic`，程序终止运行，执行`defer`函数 `fmt.Println("deferred call in fullName")`，程序控制权返回调用方`main`，执行 `main` 中 `defer` 函数`fmt.Println("deferred call in main")`，当前协程所有函数退出后就打印 `panic` 信息`panic: runtime error: last name cannot be nil`，接着打印堆栈跟踪。

`程序终止`->`执行defer`->`返回调用方`->`执行调用方defer`->`返回调用方执行defer`->`当前协程所有程序退出`->`打印panic`->`打印堆栈跟踪`->`程序结束`
## recover
内建函数 `recover` 用于重新获得 `panic` 协程的控制。

签名如下
```go
func recover() interface{}
```
只有在**延迟函数**内部调用 `recover` 才有用。延迟函数内调用 `recover` 可以取到 `panic` 错误信息，并且停止 `panic` 续发事件，程序运行恢复正常。延迟函数外部调用 `recover` 不能停止 `panic` 续发事件。
```go
func recoverName() {  
    if r := recover(); r!= nil {   //recover() 返回调用 panic 的传参，停止 panic 续发事件。
        fmt.Println("recovered from ", r)
    }
}

func fullName(firstName *string, lastName *string) {  
    defer recoverName()
    if firstName == nil {
        panic("runtime error: first name cannot be nil")
    }
    if lastName == nil {    //第 19 行程序发生 panic
        panic("runtime error: last name cannot be nil")
    }
    fmt.Printf("%s %s\n", *firstName, *lastName)
    fmt.Println("returned normally from fullName")
}

func main() {  
    defer fmt.Println("deferred call in main")
    firstName := "Elon"
    fullName(&firstName, nil)
    fmt.Println("returned normally from main")
}
```
第 19 行发生 `panic` 后会调用延迟函数 `recoverName`，它反过来调用 `recover()` 重新获得 `panic` 协程的控制，执行完 `recover()` 后 `panic` 会停止，程序控制返回到调用方（即 `main` 函数），程序接着 `fullName(&firstName, nil)` 下一句执行。

程序输出
```go
recovered from  runtime error: last name cannot be nil  
returned normally from main  
deferred call in main
```
## panic，recover 和 Go 协程
**只有在相同的 Go 协程中调用 `recover` 才有用，`recover` 不能恢复一个不同协程的 `panic`。**
```go
func recovery() {  
    if r := recover(); r != nil {
        fmt.Println("recovered:", r)
    }
}

func a() {  
    defer recovery()
    fmt.Println("Inside A")
    go b()   //重新开辟一个 go 协程 b，并在 b 中触发 panic，不能用 a 中 revocer 恢复，go b()-> b() 可以
    time.Sleep(1 * time.Second)
}

func b() {  
    fmt.Println("Inside B")
    panic("oh! B panicked")
}

func main() {  
    a()
    fmt.Println("normally returned from main")
}
```
在 `a` 协程中调用 `recover` 不能恢复 `b` 协程中的 `panic`

程序输出
```go
Inside A  
Inside B  
panic: oh! B panicked

goroutine 5 [running]:  
main.b()  
    /tmp/sandbox388039916/main.go:23 +0x80
created by main.a  
    /tmp/sandbox388039916/main.go:17 +0xc0
```
`go b()` 修改为 `b()`，就可以恢复 `panic`，因为他们在同一个协程中。
## 运行时 panic
如数组下标越界会触发运行时 `panic`，相当于调用了内置函数 `panic`，其参数由接口类型 `runtime.Error` 给出。`runtime.Error` 接口的定义如下：
```go
type Error interface {  
    error
    RuntimeError() 
}
```
创建一个运行时 error
```go
func a() {  
    n := []int{5, 7, 4}
    fmt.Println(n[3])
    fmt.Println("normally returned from a")
}
func main() {  
    a()
    fmt.Println("normally returned from main")
}
```
输出如下
```go
panic: runtime error: index out of range

goroutine 1 [running]:  
main.a()  
    /tmp/sandbox780439659/main.go:9 +0x40
main.main()  
    /tmp/sandbox780439659/main.go:13 +0x20
```
可以恢复一个运行时 `panic`
```go
func r() {  
    if r := recover(); r != nil {
        fmt.Println("Recovered", r)
    }
}

func a() {  
    defer r()
    n := []int{5, 7, 4}
    fmt.Println(n[3])
    fmt.Println("normally returned from a")
}

func main() {  
    a()
    fmt.Println("normally returned from main")
}
```
程序输出
```go
Recovered runtime error: index out of range  
normally returned from main
```
## 恢复后获得堆栈跟踪
恢复 `panic` 之后，就失去了堆栈跟踪。使用 `Debug` 包中的 `PrintStack` 函数可以打印出堆栈跟踪
```go
import (  
    "fmt"
    "runtime/debug"
)

func r() {  
    if r := recover(); r != nil {
        fmt.Println("Recovered", r)
        debug.PrintStack()    //打印堆栈跟踪
    }
}

func a() {  
    defer r()
    n := []int{5, 7, 4}
    fmt.Println(n[3])       //切片下标越界
    fmt.Println("normally returned from a")
}

func main() {  
    a()
    fmt.Println("normally returned from main")
}
```
程序输出
```go
Recovered runtime error: index out of range  
goroutine 1 [running]:  
runtime/debug.Stack(0x1042beb8, 0x2, 0x2, 0x1c)  
    /usr/local/go/src/runtime/debug/stack.go:24 +0xc0
runtime/debug.PrintStack()  
    /usr/local/go/src/runtime/debug/stack.go:16 +0x20
main.r()  
    /tmp/sandbox949178097/main.go:11 +0xe0
panic(0xf0a80, 0x17cd50)  
    /usr/local/go/src/runtime/panic.go:491 +0x2c0
main.a()  
    /tmp/sandbox949178097/main.go:18 +0x80
main.main()  
    /tmp/sandbox949178097/main.go:23 +0x20
normally returned from main
```



